Workbook

Sheet ESTUDIANTES BENEFICIADOS
A1: Convocatoria | B1: RADICADO | C1: DEPARTAMENTO | D1: SECRETARIA | E1: CODIGO_DANE_MUNICIPIO | F1: MUNICIPIO | G1: CODIGO_DANE | H1: NOMBRE_ESTABLECIMIENTO | I1: CODIGO_DANE_SEDE | J1: NOMBRE_SEDE | K1: ZONA | L1: COMPUTADOR PORTÁTIL | M1: TABLETA | N1: acudiente_nombres | O1: acudiente_documento | P1: acudiente_parentesco | Q1: acudiente_direccion | R1: acudiente_celular | S1: acudiente_correo | T1: DOCUMENTO DE IDENTIDAD | U1: NOMBRE 1 | V1: NOMBRE 2 | W1: APELLIDO 1 | X1: APELLIDO 2 | Z1: FECHA NACIMIENTO | AA1: EDAD AL 30 DE OCTUBRE CON DOCUMENTO | AB1: SEXO | AC1: GRADO | AD1: correo_estudiante | AE1: Serial Asignado | AF1: Estado Despacho | AG1: Dane sede | AH1: Lugar de Entrega | AI1: Ubicacion institucional Educativa(P-D-M) | AJ1: N° Orden de Transporte | AK1: Programa | AL1: Referencia | AM1: Descripcion | AN1: Cantidad | AO1: Serial
A2: Línea 2 — EE vinculados a Educación Superior | B2: 86471 | C2: Caldas | D2: CALDAS | E2: 17013 | F2: Aguadas | G2: 117013000306 | H2: INSTITUCION EDUCATIVA MARINO GOMEZ ESTRADA | I2: 117013000306 | J2: INSTITUCION EDUCATIVA MARINO GOMEZ ESTRADA - SEDE PRINCIPAL | K2: URBANA | L2: - | M2: 1 | N2: DURBAY PATRICIA BETANCUR CARDONA | O2: 24370801 | P2: MADRE | Q2: Cra 3 # 18-95 apto 201 | R2: 3122614536 | S2: betancurcardonadurbaypatricia@gmail.com | T2: 1059812839 | U2: MARIA | V2: FERNANDA | W2: VARGAS | X2: BETANCUR | Z2: 4/14/2010 | AA2: 15 | AB2: F | AC2: 11 | AD2: fernandavargasbetancur03@gmail.com | AF2: Despacho Programado | AG2: {=_xlfn.LET(_xlpm.n,COUNTIFS($B$2:$B2,$B2,$M$2:$M2,$M2),_xlpm.res,IF($M2=1,_xlfn._xlws.FILTER('TABLETAS ESTUDIANTES'!$C$2:$K$1000,'TABLETAS ESTUDIANTES'!$B$2:$B$1000=$B2),_xlfn._xlws.FILTER('PORTATIL ESTUDIANTES'!$C$2:$K$1000,'PORTATIL ESTUDIANTES'!$B$2:$B$1000=$B2)),IFERROR(INDEX(_xlpm.res,_xlpm.n,_xlfn.SEQUENCE(1,9)),""))} -> 117013000306 | AH2: INSTITUCION EDUCATIVA MARINO GOMEZ ESTRADA - SEDE PRINCIPAL | AI2: Aguadas | AJ2: ENTIDAD TERRITORIAL | AK2: COMITÉ DE FOCALIZACION 2026 | AL2: 45053 | AM2: BT TABLETA LENOVO IDEA TAB PRO CTO 158-25 | AN2: 1 | AO2: HA2HES5G
A3: Línea 2 — EE vinculados a Educación Superior | B3: 86471 | C3: Caldas | D3: CALDAS | E3: 17013 | F3: Aguadas | G3: 117013000306 | H3: INSTITUCION EDUCATIVA MARINO GOMEZ ESTRADA | I3: 117013000306 | J3: INSTITUCION EDUCATIVA MARINO GOMEZ ESTRADA - SEDE PRINCIPAL | K3: URBANA | L3: - | M3: 1 | N3: LUZ ADRIANA LÓPEZ MURILLO | O3: 24370572 | P3: MADRE | Q3: Cra 5 # 10-28 | R3: 3117820297 | S3: adrianayemanuel069@gmail.com | T3: 1059812816 | U3: EMANUEL | V3: 0 | W3: RAMIREZ | X3: LOPEZ | Z3: 2/17/2010 | AA3: 16 | AB3: M | AC3: 11 | AD3: ramirezlopezema@gmail.com | AF3: Despacho Programado | AG3: {=_xlfn.LET(_xlpm.n,COUNTIFS($B$2:$B3,$B3,$M$2:$M3,$M3),_xlpm.res,IF($M3=1,_xlfn._xlws.FILTER('TABLETAS ESTUDIANTES'!$C$2:$K$1000,'TABLETAS ESTUDIANTES'!$B$2:$B$1000=$B3),_xlfn._xlws.FILTER('PORTATIL ESTUDIANTES'!$C$2:$K$1000,'PORTATIL ESTUDIANTES'!$B$2:$B$1000=$B3)),IFERROR(INDEX(_xlpm.res,_xlpm.n,_xlfn.SEQUENCE(1,9)),""))} -> 117013000306 | AH3: INSTITUCION EDUCATIVA MARINO GOMEZ ESTRADA - SEDE PRINCIPAL | AI3: Aguadas | AJ3: ENTIDAD TERRITORIAL | AK3: COMITÉ DE FOCALIZACION 2026 | AL3: 45053 | AM3: BT TABLETA LENOVO IDEA TAB PRO CTO 158-25 | AN3: 1 | AO3: HA2HDZEV
A4: Línea 2 — EE vinculados a Educación Superior | B4: 32741 | C4: Caldas | D4: CALDAS | E4: 17088 | F4: Belalcázar | G4: 117088000255 | H4: INSTITUCION EDUCATIVA CRISTO REY | I4: 117088000255 | J4: INSTITUCION EDUCATIVA CRISTO REY - SEDE PRINCIPAL | K4: URBANA | L4: - | M4: 1 | N4: MARÍA ROSA SÁNCHEZ NOREÑA | O4: 24527859 | P4: MADRE | Q4: Cra 7 # 21 - 21 | R4: 3233775928 | S4: grisalessanchezjuanjose238@gmail.com | T4: 1054480366 | U4: JUAN | V4: JOSE | W4: GRISALES | X4: SANCHEZ | Z4: 9/17/2009 | AA4: 16 | AB4: M | AC4: 11 | AD4: grisalessanchezjuanjose238@gmail.com | AF4: Despacho Programado | AG4: {=_xlfn.LET(_xlpm.n,COUNTIFS($B$2:$B4,$B4,$M$2:$M4,$M4),_xlpm.res,IF($M4=1,_xlfn._xlws.FILTER('TABLETAS ESTUDIANTES'!$C$2:$K$1000,'TABLETAS ESTUDIANTES'!$B$2:$B$1000=$B4),_xlfn._xlws.FILTER('PORTATIL ESTUDIANTES'!$C$2:$K$1000,'PORTATIL ESTUDIANTES'!$B$2:$B$1000=$B4)),IFERROR(INDEX(_xlpm.res,_xlpm.n,_xlfn.SEQUENCE(1,9)),""))} -> 117088000255 | AH4: INSTITUCION EDUCATIVA CRISTO REY - SEDE PRINCIPAL | AI4: Belalcázar | AJ4: ENTIDAD TERRITORIAL | AK4: COMITÉ DE FOCALIZACION 2026 | AL4: 45053 | AM4: BT TABLETA LENOVO IDEA TAB PRO CTO 158-25 | AN4: 1 | AO4: HA2HF5YE
A5: Línea 2 — EE vinculados a Educación Superior | B5: 32741 | C5: Caldas | D5: CALDAS | E5: 17088 | F5: Belalcázar | G5: 117088000255 | H5: INSTITUCION EDUCATIVA CRISTO REY | I5: 117088000255 | J5: INSTITUCION EDUCATIVA CRISTO REY - SEDE PRINCIPAL | K5: URBANA | L5: - | M5: 1 | N5: ALEJANDRA ARISTIZÁBAL VELANDIA | O5: 24529213 | P5: MADRE | Q5: KR 4 CL 13 - 12 PISO 4 APTO 401 | R5: 3105105065 | S5: alejandraaristizabal17@hotmail.com | T5: 1089606334 | U5: JOSE | V5: MIGUEL | W5: OROZCO | X5: ARISTIZABAL | Z5: 40154 | AA5: 16 | AB5: M | AC5: 11 | AD5: jmorozcoaristizabal@gmail.com | AF5: Despacho Programado | AG5: {=_xlfn.LET(_xlpm.n,COUNTIFS($B$2:$B5,$B5,$M$2:$M5,$M5),_xlpm.res,IF($M5=1,_xlfn._xlws.FILTER('TABLETAS ESTUDIANTES'!$C$2:$K$1000,'TABLETAS ESTUDIANTES'!$B$2:$B$1000=$B5),_xlfn._xlws.FILTER('PORTATIL ESTUDIANTES'!$C$2:$K$1000,'PORTATIL ESTUDIANTES'!$B$2:$B$1000=$B5)),IFERROR(INDEX(_xlpm.res,_xlpm.n,_xlfn.SEQUENCE(1,9)),""))} -> 117088000255 | AH5: INSTITUCION EDUCATIVA CRISTO REY - SEDE PRINCIPAL | AI5: Belalcázar | AJ5: ENTIDAD TERRITORIAL | AK5: COMITÉ DE FOCALIZACION 2026 | AL5: 45053 | AM5: BT TABLETA LENOVO IDEA TAB PRO CTO 158-25 | AN5: 1 | AO5: HA2HFL9K
A6: Línea 2 — EE vinculados a Educación Superior | B6: 32741 | C6: Caldas | D6: CALDAS | E6: 17088 | F6: Belalcázar | G6: 117088000255 | H6: INSTITUCION EDUCATIVA CRISTO REY | I6: 117088000255 | J6: INSTITUCION EDUCATIVA CRISTO REY - SEDE PRINCIPAL | K6: URBANA | L6: - | M6: 1 | N6: ALBANORA RUIZ VALENCIA | O6: 24730051 | P6: MADRE | Q6: Águila alta | R6: 3137632393 | S6: ruiznora624@gmail.com | T6: 1055890618 | U6: SNEIDER | V6: 0 | W6: GALLEGO | X6: RUIZ | Z6: 40423 | AA6: 16 | AB6: M | AC6: 11 | AD6: ruizgallego1252@gmail.com | AF6: Despacho Programado | AG6: {=_xlfn.LET(_xlpm.n,COUNTIFS($B$2:$B6,$B6,$M$2:$M6,$M6),_xlpm.res,IF($M6=1,_xlfn._xlws.FILTER('TABLETAS ESTUDIANTES'!$C$2:$K$1000,'TABLETAS ESTUDIANTES'!$B$2:$B$1000=$B6),_xlfn._xlws.FILTER('PORTATIL ESTUDIANTES'!$C$2:$K$1000,'PORTATIL ESTUDIANTES'!$B$2:$B$1000=$B6)),IFERROR(INDEX(_xlpm.res,_xlpm.n,_xlfn.SEQUENCE(1,9)),""))} -> 117088000255 | AH6: INSTITUCION EDUCATIVA CRISTO REY - SEDE PRINCIPAL | AI6: Belalcázar | AJ6: ENTIDAD TERRITORIAL | AK6: COMITÉ DE FOCALIZACION 2026 | AL6: 45053 | AM6: BT TABLETA LENOVO IDEA TAB PRO CTO 158-25 | AN6: 1 | AO6: HA2HF3WN
A7: Línea 2 — EE vinculados a Educación Superior | B7: 32741 | C7: Caldas | D7: CALDAS | E7: 17088 | F7: Belalcázar | G7: 117088000255 | H7: INSTITUCION EDUCATIVA CRISTO REY | I7: 117088000255 | J7: INSTITUCION EDUCATIVA CRISTO REY - SEDE PRINCIPAL | K7: URBANA | L7: - | M7: 1 | N7: MARIA ANDREA RUEDA | O7: 1057756935 | P7: MADRE | Q7: CL 21#9-30 | R7: 3216373490 | S7: andremarrueda@gmail.com | T7: 1057757797 | U7: HAYDER | V7: HAYDER | W7: CANO | X7: RUEDA | Z7: 39908 | AA7: 16 | AB7: M | AC7: 11 | AD7: haydercanorueda428@gmail.com | AF7: Despacho Programado | AG7: {=_xlfn.LET(_xlpm.n,COUNTIFS($B$2:$B7,$B7,$M$2:$M7,$M7),_xlpm.res,IF($M7=1,_xlfn._xlws.FILTER('TABLETAS ESTUDIANTES'!$C$2:$K$1000,'TABLETAS ESTUDIANTES'!$B$2:$B$1000=$B7),_xlfn._xlws.FILTER('PORTATIL ESTUDIANTES'!$C$2:$K$1000,'PORTATIL ESTUDIANTES'!$B$2:$B$1000=$B7)),IFERROR(INDEX(_xlpm.res,_xlpm.n,_xlfn.SEQUENCE(1,9)),""))} -> 117088000255 | AH7: INSTITUCION EDUCATIVA CRISTO REY - SEDE PRINCIPAL | AI7: Belalcázar | AJ7: ENTIDAD TERRITORIAL | AK7: COMITÉ DE FOCALIZACION 2026 | AL7: 45053 | AM7: BT TABLETA LENOVO IDEA TAB PRO CTO 158-25 | AN7: 1 | AO7: HA2HEQ33
A8: Línea 2 — EE vinculados a Educación Superior | B8: 32751 | C8: Caldas | D8: CALDAS | E8: 17174 | F8: Chinchiná | G8: 117174000292 | H8: INSTITUCION EDUCATIVA SAN FRANCISCO DE PAULA | I8: 117174000292 | J8: INSTITUCIÓN EDUCATIVA SAN FRANCISCO DE PAULA - SEDE PRINCIPAL | K8: URBANA | L8: - | M8: 1 | N8: LEIDY JULIETH DUQUE SALAZAR | O8: 1054986419 | P8: MADRE | Q8: vereda los cuervos sector las escuelas | R8: 3218718906 | S8: yosthindumey2000@gmail.com | T8: 1054869093 | U8: YOSTHIN | V8: DUMEY | W8: ORTEGA | X8: DUQUE | Z8: 11/13/2008 | AA8: 17 | AB8: M | AC8: 11 | AD8: yosthindumey2000@gmail.com | AF8: Despacho Programado | AG8: {=_xlfn.LET(_xlpm.n,COUNTIFS($B$2:$B8,$B8,$M$2:$M8,$M8),_xlpm.res,IF($M8=1,_xlfn._xlws.FILTER('TABLETAS ESTUDIANTES'!$C$2:$K$1000,'TABLETAS ESTUDIANTES'!$B$2:$B$1000=$B8),_xlfn._xlws.FILTER('PORTATIL ESTUDIANTES'!$C$2:$K$1000,'PORTATIL ESTUDIANTES'!$B$2:$B$1000=$B8)),IFERROR(INDEX(_xlpm.res,_xlpm.n,_xlfn.SEQUENCE(1,9)),""))} -> 117174000292 | AH8: INSTITUCIÓN EDUCATIVA SAN FRANCISCO DE PAULA - SEDE PRINCIPAL | AI8: Chinchiná | AJ8: ENTIDAD TERRITORIAL | AK8: COMITÉ DE FOCALIZACION 2026 | AL8: 45053 | AM8: BT TABLETA LENOVO IDEA TAB PRO CTO 158-25 | AN8: 1 | AO8: HA2HFZ91
A9: Línea 2 — EE vinculados a Educación Superior | B9: 18499 | C9: Caldas | D9: CALDAS | E9: 17174 | F9: Chinchiná | G9: 117174000349 | H9: INSTITUCION EDUCATIVA SANTA TERESITA | I9: 117174000349 | J9: INSTITUCIÓN EDUCATIVA SANTA TERESITA - SEDE PRINCIPAL | K9: URBANA | L9: - | M9: 1 | N9: PAULA ANDREA LOPEZ TRUJILLO | O9: 38561494 | P9: MADRE | Q9: cra 7 10-07 | R9: 3227937549 | S9: paulaandrealopeztrujillo03@gmail.com | T9: 1107859445 | U9: JOEL | V9: LORENZO | W9: GIRALDO | X9: LOPEZ | Z9: 1/30/2010 | AA9: 16 | AB9: M | AC9: 11 | AD9: joel.giraldo.lopez2024@gmail.com | AF9: Despacho Programado | AG9: {=_xlfn.LET(_xlpm.n,COUNTIFS($B$2:$B9,$B9,$M$2:$M9,$M9),_xlpm.res,IF($M9=1,_xlfn._xlws.FILTER('TABLETAS ESTUDIANTES'!$C$2:$K$1000,'TABLETAS ESTUDIANTES'!$B$2:$B$1000=$B9),_xlfn._xlws.FILTER('PORTATIL ESTUDIANTES'!$C$2:$K$1000,'PORTATIL ESTUDIANTES'!$B$2:$B$1000=$B9)),IFERROR(INDEX(_xlpm.res,_xlpm.n,_xlfn.SEQUENCE(1,9)),""))} -> 117174000349 | AH9: INSTITUCIÓN EDUCATIVA SANTA TERESITA - SEDE PRINCIPAL | AI9: Chinchiná | AJ9: ENTIDAD TERRITORIAL | AK9: COMITÉ DE FOCALIZACION 2026 | AL9: 45053 | AM9: BT TABLETA LENOVO IDEA TAB PRO CTO 158-25 | AN9: 1 | AO9: HA2HG0GP
A10: Línea 2 — EE vinculados a Educación Superior | B10: 18499 | C10: Caldas | D10: CALDAS | E10: 17174 | F10: Chinchiná | G10: 117174000349 | H10: INSTITUCION EDUCATIVA SANTA TERESITA | I10: 117174000349 | J10: INSTITUCIÓN EDUCATIVA SANTA TERESITA - SEDE PRINCIPAL | K10: URBANA | L10: - | M10: 1 | N10: DEYVER ARCILA CORTES | O10: 18399293 | P10: PADRE | Q10: cra 17a # 8a - 03 | R10: 3146061304 | S10: deyverarcila1980@gmail.com | T10: 1054871365 | U10: MANUELA | V10: 0 | W10: ARCILA | X10: ARCILA | Z10: 39911 | AA10: 16 | AB10: F | AC10: 11 | AD10: manuarcila2009@gmail.com | AF10: Despacho Programado | AG10: {=_xlfn.LET(_xlpm.n,COUNTIFS($B$2:$B10,$B10,$M$2:$M10,$M10),_xlpm.res,IF($M10=1,_xlfn._xlws.FILTER('TABLETAS ESTUDIANTES'!$C$2:$K$1000,'TABLETAS ESTUDIANTES'!$B$2:$B$1000=$B10),_xlfn._xlws.FILTER('PORTATIL ESTUDIANTES'!$C$2:$K$1000,'PORTATIL ESTUDIANTES'!$B$2:$B$1000=$B10)),IFERROR(INDEX(_xlpm.res,_xlpm.n,_xlfn.SEQUENCE(1,9)),""))} -> 117174000349 | AH10: INSTITUCIÓN EDUCATIVA SANTA TERESITA - SEDE PRINCIPAL | AI10: Chinchiná | AJ10: ENTIDAD TERRITORIAL | AK10: COMITÉ DE FOCALIZACION 2026 | AL10: 45053 | AM10: BT TABLETA LENOVO IDEA TAB PRO CTO 158-25 | AN10: 1 | AO10: HA2HES59
A11: Línea 2 — EE vinculados a Educación Superior | B11: 18499 | C11: Caldas | D11: CALDAS | E11: 17174 | F11: Chinchiná | G11: 117174000349 | H11: INSTITUCION EDUCATIVA SANTA TERESITA | I11: 117174000349 | J11: INSTITUCIÓN EDUCATIVA SANTA TERESITA - SEDE PRINCIPAL | K11: URBANA | L11: - | M11: 1 | N11: LADY TATIANA GIRALDO PARRA | O11: 1088261904 | P11: MADRE | Q11: CARRERA 12C # 7-07 URBANIZACIÓN LA VICTORIA CASA 22 | R11: 3106423884 | S11: tatygp22@gmail.com | T11: 1137061910 | U11: MARIANA | V11: 0 | W11: GIRALDO | X11: PARRA | Z11: 39883 | AA11: 16 | AB11: F | AC11: 11 | AD11: marianagiraldoparra09@gmail.com | AF11: Despacho Programado | AG11: {=_xlfn.LET(_xlpm.n,COUNTIFS($B$2:$B11,$B11,$M$2:$M11,$M11),_xlpm.res,IF($M11=1,_xlfn._xlws.FILTER('TABLETAS ESTUDIANTES'!$C$2:$K$1000,'TABLETAS ESTUDIANTES'!$B$2:$B$1000=$B11),_xlfn._xlws.FILTER('PORTATIL ESTUDIANTES'!$C$2:$K$1000,'PORTATIL ESTUDIANTES'!$B$2:$B$1000=$B11)),IFERROR(INDEX(_xlpm.res,_xlpm.n,_xlfn.SEQUENCE(1,9)),""))} -> 117174000349 | AH11: INSTITUCIÓN EDUCATIVA SANTA TERESITA - SEDE PRINCIPAL | AI11: Chinchiná | AJ11: ENTIDAD TERRITORIAL | AK11: COMITÉ DE FOCALIZACION 2026 | AL11: 45053 | AM11: BT TABLETA LENOVO IDEA TAB PRO CTO 158-25 | AN11: 1 | AO11: HA2HDZLA
A12: Línea 2 — EE vinculados a Educación Superior | B12: 18499 | C12: Caldas | D12: CALDAS | E12: 17174 | F12: Chinchiná | G12: 117174000349 | H12: INSTITUCION EDUCATIVA SANTA TERESITA | I12: 117174000349 | J12: INSTITUCIÓN EDUCATIVA SANTA TERESITA - SEDE PRINCIPAL | K12: URBANA | L12: - | M12: 1 | N12: JENNY VANESSA TABARES LOZANO | O12: 30361348 | P12: MADRE | Q12: Cra 15a#8D-31 | R12: 3105252506 | S12: valerytabares921@gmail.com | T12: 1054872974 | U12: VALERY | V12: 0 | W12: CARDENAS | X12: TABARES | Z12: 2/20/2010 | AA12: 16 | AB12: F | AC12: 11 | AD12: valerytabares921@gmail.com | AF12: Despacho Programado | AG12: {=_xlfn.LET(_xlpm.n,COUNTIFS($B$2:$B12,$B12,$M$2:$M12,$M12),_xlpm.res,IF($M12=1,_xlfn._xlws.FILTER('TABLETAS ESTUDIANTES'!$C$2:$K$1000,'TABLETAS ESTUDIANTES'!$B$2:$B$1000=$B12),_xlfn._xlws.FILTER('PORTATIL ESTUDIANTES'!$C$2:$K$1000,'PORTATIL ESTUDIANTES'!$B$2:$B$1000=$B12)),IFERROR(INDEX(_xlpm.res,_xlpm.n,_xlfn.SEQUENCE(1,9)),""))} -> 117174000349 | AH12: INSTITUCIÓN EDUCATIVA SANTA TERESITA - SEDE PRINCIPAL | AI12: Chinchiná | AJ12: ENTIDAD TERRITORIAL | AK12: COMITÉ DE FOCALIZACION 2026 | AL12: 45053 | AM12: BT TABLETA LENOVO IDEA TAB PRO CTO 158-25 | AN12: 1 | AO12: HA2HGSRY
A13: Línea 2 — EE vinculados a Educación Superior | B13: 18499 | C13: Caldas | D13: CALDAS | E13: 17174 | F13: Chinchiná | G13: 117174000349 | H13: INSTITUCION EDUCATIVA SANTA TERESITA | I13: 117174000349 | J13: INSTITUCIÓN EDUCATIVA SANTA TERESITA - SEDE PRINCIPAL | K13: URBANA | L13: - | M13: 1 | N13: FLORALBA LOPEZ LONDOÑO | O13: 30358460 | P13: MADRE | Q13: crr10# 6-36 | R13: 3105142204 | S13: floralbalopez00@gmail.com | T13: 1054480110 | U13: DILAN | V13: ESTEBAN | W13: RUDAS | X13: LOPEZ | Z13: 39733 | AA13: 17 | AB13: M | AC13: 11 | AD13: dilanestebanrudas@gmail.com | AF13: Despacho Programado | AG13: {=_xlfn.LET(_xlpm.n,COUNTIFS($B$2:$B13,$B13,$M$2:$M13,$M13),_xlpm.res,IF($M13=1,_xlfn._xlws.FILTER('TABLETAS ESTUDIANTES'!$C$2:$K$1000,'TABLETAS ESTUDIANTES'!$B$2:$B$1000=$B13),_xlfn._xlws.FILTER('PORTATIL ESTUDIANTES'!$C$2:$K$1000,'PORTATIL ESTUDIANTES'!$B$2:$B$1000=$B13)),IFERROR(INDEX(_xlpm.res,_xlpm.n,_xlfn.SEQUENCE(1,9)),""))} -> 117174000349 | AH13: INSTITUCIÓN EDUCATIVA SANTA TERESITA - SEDE PRINCIPAL | AI13: Chinchiná | AJ13: ENTIDAD TERRITORIAL | AK13: COMITÉ DE FOCALIZACION 2026 | AL13: 45053 | AM13: BT TABLETA LENOVO IDEA TAB PRO CTO 158-25 | AN13: 1 | AO13: HA2HDHTY
A14: Línea 2 — EE vinculados a Educación Superior | B14: 18499 | C14: Caldas | D14: CALDAS | E14: 17174 | F14: Chinchiná | G14: 117174000349 | H14: INSTITUCION EDUCATIVA SANTA TERESITA | I14: 117174000349 | J14: INSTITUCIÓN EDUCATIVA SANTA TERESITA - SEDE PRINCIPAL | K14: URBANA | L14: - | M14: 1 | N14: LAZARO ANTONIO VALENCIA CORRALES | O14: 4414200 | P14: PADRE | Q14: Vereda bajo español Finca caja de oro | R14: 3218471897 | S14: Valciajp@gmail.com | T14: 1127386550 | U14: JUAN | V14: PABLO | W14: VALENCIA | X14: GONZALEZ | Z14: 40153 | AA14: 16 | AB14: M | AC14: 11 | AD14: Valciajp@gmail.com | AF14: Despacho Programado | AG14: {=_xlfn.LET(_xlpm.n,COUNTIFS($B$2:$B14,$B14,$M$2:$M14,$M14),_xlpm.res,IF($M14=1,_xlfn._xlws.FILTER('TABLETAS ESTUDIANTES'!$C$2:$K$1000,'TABLETAS ESTUDIANTES'!$B$2:$B$1000=$B14),_xlfn._xlws.FILTER('PORTATIL ESTUDIANTES'!$C$2:$K$1000,'PORTATIL ESTUDIANTES'!$B$2:$B$1000=$B14)),IFERROR(INDEX(_xlpm.res,_xlpm.n,_xlfn.SEQUENCE(1,9)),""))} -> 117174000349 | AH14: INSTITUCIÓN EDUCATIVA SANTA TERESITA - SEDE PRINCIPAL | AI14: Chinchiná | AJ14: ENTIDAD TERRITORIAL | AK14: COMITÉ DE FOCALIZACION 2026 | AL14: 45053 | AM14: BT TABLETA LENOVO IDEA TAB PRO CTO 158-25 | AN14: 1 | AO14: HA2HDDHS
A15: Línea 2 — EE vinculados a Educación Superior | B15: 18499 | C15: Caldas | D15: CALDAS | E15: 17174 | F15: Chinchiná | G15: 117174000349 | H15: INSTITUCION EDUCATIVA SANTA TERESITA | I15: 117174000349 | J15: INSTITUCIÓN EDUCATIVA SANTA TERESITA - SEDE PRINCIPAL | K15: URBANA | L15: - | M15: 1 | N15: FRANCIA AYER RAMÍREZ | O15: 30331559 | P15: MADRE | Q15: Carrera 11 Calle 6 #11-19 | R15: 3044482085 | S15: tamayoemmanuel90@gmail.com | T15: 1058140140 | U15: EMANUEL | V15: 0 | W15: TAMAYO | X15: RAMIREZ | Z15: 2/21/2009 | AA15: 17 | AB15: M | AC15: 11 | AD15: tamayoramirezemmanuel21@gmail.com | AF15: Despacho Programado | AG15: {=_xlfn.LET(_xlpm.n,COUNTIFS($B$2:$B15,$B15,$M$2:$M15,$M15),_xlpm.res,IF($M15=1,_xlfn._xlws.FILTER('TABLETAS ESTUDIANTES'!$C$2:$K$1000,'TABLETAS ESTUDIANTES'!$B$2:$B$1000=$B15),_xlfn._xlws.FILTER('PORTATIL ESTUDIANTES'!$C$2:$K$1000,'PORTATIL ESTUDIANTES'!$B$2:$B$1000=$B15)),IFERROR(INDEX(_xlpm.res,_xlpm.n,_xlfn.SEQUENCE(1,9)),""))} -> 117174000349 | AH15: INSTITUCIÓN EDUCATIVA SANTA TERESITA - SEDE PRINCIPAL | AI15: Chinchiná | AJ15: ENTIDAD TERRITORIAL | AK15: COMITÉ DE FOCALIZACION 2026 | AL15: 45053 | AM15: BT TABLETA LENOVO IDEA TAB PRO CTO 158-25 | AN15: 1 | AO15: HA2HEN5S
A16: Línea 2 — EE vinculados a Educación Superior | B16: 84731 | C16: Caldas | D16: CALDAS | E16: 17433 | F16: Manzanares | G16: 117433000379 | H16: INSTITUCION EDUCATIVA MANZANARES | I16: 117433000379 | J16: INSTITUCION EDUCATIVA MANZANARES - SEDE PRINCIPAL | K16: URBANA | L16: - | M16: 1 | N16: MARITZA SANCHEZ GALEANO | O16: 24729296 | P16: MADRE | Q16: cra5 #8-13 | R16: 3223607969 | S16: masaga2472@gmail.com | T16: 1107981101 | U16: ANDRES | V16: FELIPE | W16: FRANCO | X16: SANCHEZ | Z16: 40271 | AA16: 16 | AB16: M | AC16: 11 | AD16: andresfelipefrancosanchez181@gmail.com | AF16: Despacho Programado | AG16: {=_xlfn.LET(_xlpm.n,COUNTIFS($B$2:$B16,$B16,$M$2:$M16,$M16),_xlpm.res,IF($M16=1,_xlfn._xlws.FILTER('TABLETAS ESTUDIANTES'!$C$2:$K$1000,'TABLETAS ESTUDIANTES'!$B$2:$B$1000=$B16),_xlfn._xlws.FILTER('PORTATIL ESTUDIANTES'!$C$2:$K$1000,'PORTATIL ESTUDIANTES'!$B$2:$B$1000=$B16)),IFERROR(INDEX(_xlpm.res,_xlpm.n,_xlfn.SEQUENCE(1,9)),""))} -> 117433000379 | AH16: INSTITUCION EDUCATIVA MANZANARES - SEDE PRINCIPAL | AI16: Manzanares | AJ16: ENTIDAD TERRITORIAL | AK16: COMITÉ DE FOCALIZACION 2026 | AL16: 45053 | AM16: BT TABLETA LENOVO IDEA TAB PRO CTO 158-25 | AN16: 1 | AO16: HA2HCYGP
A17: Línea 2 — EE vinculados a Educación Superior | B17: 84731 | C17: Caldas | D17: CALDAS | E17: 17433 | F17: Manzanares | G17: 117433000379 | H17: INSTITUCION EDUCATIVA MANZANARES | I17: 117433000379 | J17: INSTITUCION EDUCATIVA MANZANARES - SEDE PRINCIPAL | K17: URBANA | L17: - | M17: 1 | N17: YARLEDY GARCIA CARVAJAL | O17: 24731301 | P17: MADRE | Q17: Barrio Lombo | R17: 3234872217 | S17: Valenciagyarlenyy@gmail.com | T17: 1055890622 | U17: MARIA | V17: JOSE | W17: VALENCIA | X17: GARCIA | Z17: 2/20/2010 | AA17: 16 | AB17: F | AC17: 11 | AD17: yarle3245@gmail.com | AF17: Despacho Programado | AG17: {=_xlfn.LET(_xlpm.n,COUNTIFS($B$2:$B17,$B17,$M$2:$M17,$M17),_xlpm.res,IF($M17=1,_xlfn._xlws.FILTER('TABLETAS ESTUDIANTES'!$C$2:$K$1000,'TABLETAS ESTUDIANTES'!$B$2:$B$1000=$B17),_xlfn._xlws.FILTER('PORTATIL ESTUDIANTES'!$C$2:$K$1000,'PORTATIL ESTUDIANTES'!$B$2:$B$1000=$B17)),IFERROR(INDEX(_xlpm.res,_xlpm.n,_xlfn.SEQUENCE(1,9)),""))} -> 117433000379 | AH17: INSTITUCION EDUCATIVA MANZANARES - SEDE PRINCIPAL | AI17: Manzanares | AJ17: ENTIDAD TERRITORIAL | AK17: COMITÉ DE FOCALIZACION 2026 | AL17: 45053 | AM17: BT TABLETA LENOVO IDEA TAB PRO CTO 158-25 | AN17: 1 | AO17: HA2HFQ9E
A18: Línea 2 — EE vinculados a Educación Superior | B18: 84731 | C18: Caldas | D18: CALDAS | E18: 17433 | F18: Manzanares | G18: 117433000379 | H18: INSTITUCION EDUCATIVA MANZANARES | I18: 117433000379 | J18: INSTITUCION EDUCATIVA MANZANARES - SEDE PRINCIPAL | K18: URBANA | L18: - | M18: 1 | N18: LEIDY TATIANA JARAMILLO MONTES | O18: 1058843925 | P18: MADRE | Q18: Calle 6 3 33 | R18: 3133727502 | S18: tatiana.jaramillom@hotmail.com | T18: 1054871822 | U18: GERONIMO | V18: 0 | W18: HINCAPIE | X18: JARAMILLO | Z18: 10/29/2009 | AA18: 16 | AB18: M | AC18: 11 | AD18: hincapiejaramillogeronimo@gmail.com | AF18: Despacho Programado | AG18: {=_xlfn.LET(_xlpm.n,COUNTIFS($B$2:$B18,$B18,$M$2:$M18,$M18),_xlpm.res,IF($M18=1,_xlfn._xlws.FILTER('TABLETAS ESTUDIANTES'!$C$2:$K$1000,'TABLETAS ESTUDIANTES'!$B$2:$B$1000=$B18),_xlfn._xlws.FILTER('PORTATIL ESTUDIANTES'!$C$2:$K$1000,'PORTATIL ESTUDIANTES'!$B$2:$B$1000=$B18)),IFERROR(INDEX(_xlpm.res,_xlpm.n,_xlfn.SEQUENCE(1,9)),""))} -> 117433000379 | AH18: INSTITUCION EDUCATIVA MANZANARES - SEDE PRINCIPAL | AI18: Manzanares | AJ18: ENTIDAD TERRITORIAL | AK18: COMITÉ DE FOCALIZACION 2026 | AL18: 45053 | AM18: BT TABLETA LENOVO IDEA TAB PRO CTO 158-25 | AN18: 1 | AO18: HA2HG494
A19: Línea 2 — EE vinculados a Educación Superior | B19: 84731 | C19: Caldas | D19: CALDAS | E19: 17433 | F19: Manzanares | G19: 117433000379 | H19: INSTITUCION EDUCATIVA MANZANARES | I19: 117433000379 | J19: INSTITUCION EDUCATIVA MANZANARES - SEDE PRINCIPAL | K19: URBANA | L19: - | M19: 1 | N19: MARIO ANDRES NIETO GIL | O19: 1094886858 | P19: PADRE | Q19: Calle 11 #5-05 | R19: 3122145613 | S19: mangi@hotmail.com | T19: 1090275889 | U19: SOFIA | V19: 0 | W19: NIETO | X19: OSORIO | Z19: 4/24/2009 | AA19: 16 | AB19: F | AC19: 11 | AD19: nieto.245600@gmail.com | AF19: Despacho Programado | AG19: {=_xlfn.LET(_xlpm.n,COUNTIFS($B$2:$B19,$B19,$M$2:$M19,$M19),_xlpm.res,IF($M19=1,_xlfn._xlws.FILTER('TABLETAS ESTUDIANTES'!$C$2:$K$1000,'TABLETAS ESTUDIANTES'!$B$2:$B$1000=$B19),_xlfn._xlws.FILTER('PORTATIL ESTUDIANTES'!$C$2:$K$1000,'PORTATIL ESTUDIANTES'!$B$2:$B$1000=$B19)),IFERROR(INDEX(_xlpm.res,_xlpm.n,_xlfn.SEQUENCE(1,9)),""))} -> 117433000379 | AH19: INSTITUCION EDUCATIVA MANZANARES - SEDE PRINCIPAL | AI19: Manzanares | AJ19: ENTIDAD TERRITORIAL | AK19: COMITÉ DE FOCALIZACION 2026 | AL19: 45053 | AM19: BT TABLETA LENOVO IDEA TAB PRO CTO 158-25 | AN19: 1 | AO19: HA2HFE78
A20: Línea 2 — EE vinculados a Educación Superior | B20: 84731 | C20: Caldas | D20: CALDAS | E20: 17433 | F20: Manzanares | G20: 117433000379 | H20: INSTITUCION EDUCATIVA MANZANARES | I20: 117433000379 | J20: INSTITUCION EDUCATIVA MANZANARES - SEDE PRINCIPAL | K20: URBANA | L20: - | M20: 1 | N20: DIANA FARLEDY CARVAJAL LOPEZ | O20: 1057782308 | P20: MADRE | Q20: Calle 1#2_04 mirador esquina | R20: 3176320305 | S20: carvajaldiana753@gmail.com | T20: 1054556929 | U20: LUISA | V20: FERNANDA | W20: MARTINEZ | X20: CARVAJAL | Z20: 4/19/2010 | AA20: 15 | AB20: F | AC20: 11 | AD20: luisafernandamartinezcarvajal@gmail.com | AF20: Despacho Programado | AG20: {=_xlfn.LET(_xlpm.n,COUNTIFS($B$2:$B20,$B20,$M$2:$M20,$M20),_xlpm.res,IF($M20=1,_xlfn._xlws.FILTER('TABLETAS ESTUDIANTES'!$C$2:$K$1000,'TABLETAS ESTUDIANTES'!$B$2:$B$1000=$B20),_xlfn._xlws.FILTER('PORTATIL ESTUDIANTES'!$C$2:$K$1000,'PORTATIL ESTUDIANTES'!$B$2:$B$1000=$B20)),IFERROR(INDEX(_xlpm.res,_xlpm.n,_xlfn.SEQUENCE(1,9)),""))} -> 117433000379 | AH20: INSTITUCION EDUCATIVA MANZANARES - SEDE PRINCIPAL | AI20: Manzanares | AJ20: ENTIDAD TERRITORIAL | AK20: COMITÉ DE FOCALIZACION 2026 | AL20: 45053 | AM20: BT TABLETA LENOVO IDEA TAB PRO CTO 158-25 | AN20: 1 | AO20: HA2HGSRJ
A21: Línea 2 — EE vinculados a Educación Superior | B21: 9089 | C21: Caldas | D21: CALDAS | E21: 17444 | F21: Marquetalia | G21: 217444000138 | H21: INSTITUCION EDUCATIVA EL PLACER | I21: 217444000138 | J21: INSTITUCION EDUCATIVA EL PLACER - SEDE PRINCIPAL | K21: RURAL | L21: 1 | M21: - | N21: EDWIN OSORIO GUARÍN | O21: 75004320 | P21: PADRE | Q21: Vereda Buenos Aires | R21: 3117625031 | S21: edwinosoriog5@gmail.com | T21: 1058200418 | U21: JUANA | V21: JULIETH | W21: OSORIO | X21: OSORIO | Z21: 1/30/2010 | AA21: 16 | AB21: F | AC21: 11 | AD21: juanajuliethosorio@gmail.com | AF21: Despacho Programado | AG21: {=_xlfn.LET(_xlpm.n,COUNTIFS($B$2:$B21,$B21,$M$2:$M21,$M21),_xlpm.res,IF($M21=1,_xlfn._xlws.FILTER('TABLETAS ESTUDIANTES'!$C$2:$K$1000,'TABLETAS ESTUDIANTES'!$B$2:$B$1000=$B21),_xlfn._xlws.FILTER('PORTATIL ESTUDIANTES'!$C$2:$K$1000,'PORTATIL ESTUDIANTES'!$B$2:$B$1000=$B21)),IFERROR(INDEX(_xlpm.res,_xlpm.n,_xlfn.SEQUENCE(1,9)),""))} -> 217444000138 | AH21: INSTITUCION EDUCATIVA EL PLACER - SEDE PRINCIPAL | AI21: Marquetalia | AJ21: ENTIDAD TERRITORIAL | AK21: COMITÉ DE FOCALIZACION 2026 | AL21: 45030 | AM21: PORTÁTIL 14" HEWLETT PACKARD, PROBOOK 445 14 INCH G11 RYZEN 3 7335U - OC 148772 | AN21: 1 | AO21: 5CD532768Y
A22: Línea 2 — EE vinculados a Educación Superior | B22: 9089 | C22: Caldas | D22: CALDAS | E22: 17444 | F22: Marquetalia | G22: 217444000138 | H22: INSTITUCION EDUCATIVA EL PLACER | I22: 217444000138 | J22: INSTITUCION EDUCATIVA EL PLACER - SEDE PRINCIPAL | K22: RURAL | L22: 1 | M22: - | N22: NARLIDIS MEJIA HERNANDEZ | O22: 22143357 | P22: MADRE | Q22: Vereda el porvenir | R22: 3145956024 | S22: mejianarlidis6@gmail.com | T22: 1053809439 | U22: ANDRES | V22: FELIPE | W22: OSORIO | X22: MEJIA | Z22: 2/21/2009 | AA22: 17 | AB22: M | AC22: 11 | AD22: narlidismejia941mail.com@gmail.com | AF22: Despacho Programado | AG22: {=_xlfn.LET(_xlpm.n,COUNTIFS($B$2:$B22,$B22,$M$2:$M22,$M22),_xlpm.res,IF($M22=1,_xlfn._xlws.FILTER('TABLETAS ESTUDIANTES'!$C$2:$K$1000,'TABLETAS ESTUDIANTES'!$B$2:$B$1000=$B22),_xlfn._xlws.FILTER('PORTATIL ESTUDIANTES'!$C$2:$K$1000,'PORTATIL ESTUDIANTES'!$B$2:$B$1000=$B22)),IFERROR(INDEX(_xlpm.res,_xlpm.n,_xlfn.SEQUENCE(1,9)),""))} -> 217444000138 | AH22: INSTITUCION EDUCATIVA EL PLACER - SEDE PRINCIPAL | AI22: Marquetalia | AJ22: ENTIDAD TERRITORIAL | AK22: COMITÉ DE FOCALIZACION 2026 | AL22: 45030 | AM22: PORTÁTIL 14" HEWLETT PACKARD, PROBOOK 445 14 INCH G11 RYZEN 3 7335U - OC 148772 | AN22: 1 | AO22: 5CD53276Z1
A23: Línea 2 — EE vinculados a Educación Superior | B23: 21879 | C23: Caldas | D23: CALDAS | E23: 17495 | F23: Norcasia | G23: 117495005407 | H23: INSTITUCION EDUCATIVA SAN GERARDO MARIA MAYELA | I23: 117495005407 | J23: INSTITUCIÓN EDUCATIVA SAN GERARDO MARIA MAYELA - SEDE PRINCIPAL | K23: URBANA | L23: 1 | M23: - | N23: LUIZA FERNANDA RODRIGUEZ GALLEGO | O23: 1128625495 | P23: MADRE | Q23: MANZANA 35 CASA 97 BARRIO SAN MARIANO | R23: 3143518810 | S23: luizafer_815@hotmail.com | T23: 1054555724 | U23: JUAN | V23: DAVID | W23: BEDOYA | X23: RODRIGUEZ | Z23: 40096 | AA23: 16 | AB23: M | AC23: 11 | AD23: juand20024@icloud.com | AF23: Despacho Programado | AG23: {=_xlfn.LET(_xlpm.n,COUNTIFS($B$2:$B23,$B23,$M$2:$M23,$M23),_xlpm.res,IF($M23=1,_xlfn._xlws.FILTER('TABLETAS ESTUDIANTES'!$C$2:$K$1000,'TABLETAS ESTUDIANTES'!$B$2:$B$1000=$B23),_xlfn._xlws.FILTER('PORTATIL ESTUDIANTES'!$C$2:$K$1000,'PORTATIL ESTUDIANTES'!$B$2:$B$1000=$B23)),IFERROR(INDEX(_xlpm.res,_xlpm.n,_xlfn.SEQUENCE(1,9)),""))} -> 117495005407 | AH23: INSTITUCIÓN EDUCATIVA SAN GERARDO MARIA MAYELA - SEDE PRINCIPAL | AI23: Norcasia | AJ23: ENTIDAD TERRITORIAL | AK23: COMITÉ DE FOCALIZACION 2026 | AL23: 45030 | AM23: PORTÁTIL 14" HEWLETT PACKARD, PROBOOK 445 14 INCH G11 RYZEN 3 7335U - OC 148772 | AN23: 1 | AO23: 5CD532766F
A24: Línea 2 — EE vinculados a Educación Superior | B24: 21879 | C24: Caldas | D24: CALDAS | E24: 17495 | F24: Norcasia | G24: 117495005407 | H24: INSTITUCION EDUCATIVA SAN GERARDO MARIA MAYELA | I24: 117495005407 | J24: INSTITUCIÓN EDUCATIVA SAN GERARDO MARIA MAYELA - SEDE PRINCIPAL | K24: URBANA | L24: 1 | M24: - | N24: YURIANA YERLEIDY RINCON FLOREZ | O24: 1128624188 | P24: MADRE | Q24: ALTO DE LOS PINOS BL C AP 31 PISO 2 | R24: 3232879104 | S24: luizafer_815@hotmail.com | T24: 1012376245 | U24: DAVID | V24: ESTEBAN | W24: CRISTANCHO | X24: RINCON | Z24: 39937 | AA24: 16 | AB24: M | AC24: 11 | AD24: yyrf89@gmail.com | AF24: Despacho Programado | AG24: {=_xlfn.LET(_xlpm.n,COUNTIFS($B$2:$B24,$B24,$M$2:$M24,$M24),_xlpm.res,IF($M24=1,_xlfn._xlws.FILTER('TABLETAS ESTUDIANTES'!$C$2:$K$1000,'TABLETAS ESTUDIANTES'!$B$2:$B$1000=$B24),_xlfn._xlws.FILTER('PORTATIL ESTUDIANTES'!$C$2:$K$1000,'PORTATIL ESTUDIANTES'!$B$2:$B$1000=$B24)),IFERROR(INDEX(_xlpm.res,_xlpm.n,_xlfn.SEQUENCE(1,9)),""))} -> 117495005407 | AH24: INSTITUCIÓN EDUCATIVA SAN GERARDO MARIA MAYELA - SEDE PRINCIPAL | AI24: Norcasia | AJ24: ENTIDAD TERRITORIAL | AK24: COMITÉ DE FOCALIZACION 2026 | AL24: 45030 | AM24: PORTÁTIL 14" HEWLETT PACKARD, PROBOOK 445 14 INCH G11 RYZEN 3 7335U - OC 148772 | AN24: 1 | AO24: 5CD5320LGS
A25: Línea 2 — EE vinculados a Educación Superior | B25: 21879 | C25: Caldas | D25: CALDAS | E25: 17495 | F25: Norcasia | G25: 117495005407 | H25: INSTITUCION EDUCATIVA SAN GERARDO MARIA MAYELA | I25: 117495005407 | J25: INSTITUCIÓN EDUCATIVA SAN GERARDO MARIA MAYELA - SEDE PRINCIPAL | K25: URBANA | L25: 1 | M25: - | N25: ADRIANA MARÍA MEJIA | O25: 24716677 | P25: MADRE | Q25: Nueva esperanza bloque 4 apartamento 503 | R25: 3206226041 | S25: luizafer_815@hotmail.com | T25: 1128625906 | U25: MIGUEL | V25: ANGEL | W25: TRUJILLO | X25: MEJIA | Z25: 40212 | AA25: 16 | AB25: M | AC25: 11 | AD25: mejiaquintero884@gmail.com | AF25: Despacho Programado | AG25: {=_xlfn.LET(_xlpm.n,COUNTIFS($B$2:$B25,$B25,$M$2:$M25,$M25),_xlpm.res,IF($M25=1,_xlfn._xlws.FILTER('TABLETAS ESTUDIANTES'!$C$2:$K$1000,'TABLETAS ESTUDIANTES'!$B$2:$B$1000=$B25),_xlfn._xlws.FILTER('PORTATIL ESTUDIANTES'!$C$2:$K$1000,'PORTATIL ESTUDIANTES'!$B$2:$B$1000=$B25)),IFERROR(INDEX(_xlpm.res,_xlpm.n,_xlfn.SEQUENCE(1,9)),""))} -> 117495005407 | AH25: INSTITUCIÓN EDUCATIVA SAN GERARDO MARIA MAYELA - SEDE PRINCIPAL | AI25: Norcasia | AJ25: ENTIDAD TERRITORIAL | AK25: COMITÉ DE FOCALIZACION 2026 | AL25: 45030 | AM25: PORTÁTIL 14" HEWLETT PACKARD, PROBOOK 445 14 INCH G11 RYZEN 3 7335U - OC 148772 | AN25: 1 | AO25: 5CD5328V62
A26: Línea 2 — EE vinculados a Educación Superior | B26: 21879 | C26: Caldas | D26: CALDAS | E26: 17495 | F26: Norcasia | G26: 117495005407 | H26: INSTITUCION EDUCATIVA SAN GERARDO MARIA MAYELA | I26: 117495005407 | J26: INSTITUCIÓN EDUCATIVA SAN GERARDO MARIA MAYELA - SEDE PRINCIPAL | K26: URBANA | L26: 1 | M26: - | N26: MERCEDES BERMUDEZ | O26: 1128624528 | P26: MADRE | Q26: BARRIO MARISOL MANRIQUE ETAPA 2 - CASA #21 | R26: 3137555728 | S26: luizafer_815@hotmail.com | T26: 1128625749 | U26: OSCAR | V26: DAVID | W26: ROA | X26: BERMUDEZ | Z26: 40064 | AA26: 16 | AB26: M | AC26: 11 | AD26: roabermudezoscardavid@gmail.com | AF26: Despacho Programado | AG26: {=_xlfn.LET(_xlpm.n,COUNTIFS($B$2:$B26,$B26,$M$2:$M26,$M26),_xlpm.res,IF($M26=1,_xlfn._xlws.FILTER('TABLETAS ESTUDIANTES'!$C$2:$K$1000,'TABLETAS ESTUDIANTES'!$B$2:$B$1000=$B26),_xlfn._xlws.FILTER('PORTATIL ESTUDIANTES'!$C$2:$K$1000,'PORTATIL ESTUDIANTES'!$B$2:$B$1000=$B26)),IFERROR(INDEX(_xlpm.res,_xlpm.n,_xlfn.SEQUENCE(1,9)),""))} -> 117495005407 | AH26: INSTITUCIÓN EDUCATIVA SAN GERARDO MARIA MAYELA - SEDE PRINCIPAL | AI26: Norcasia | AJ26: ENTIDAD TERRITORIAL | AK26: COMITÉ DE FOCALIZACION 2026 | AL26: 45030 | AM26: PORTÁTIL 14" HEWLETT PACKARD, PROBOOK 445 14 INCH G11 RYZEN 3 7335U - OC 148772 | AN26: 1 | AO26: 5CD5320LFT
A27: Línea 2 — EE vinculados a Educación Superior | B27: 21879 | C27: Caldas | D27: CALDAS | E27: 17495 | F27: Norcasia | G27: 117495005407 | H27: INSTITUCION EDUCATIVA SAN GERARDO MARIA MAYELA | I27: 117495005407 | J27: INSTITUCIÓN EDUCATIVA SAN GERARDO MARIA MAYELA - SEDE PRINCIPAL | K27: URBANA | L27: 1 | M27: - | N27: YENSY LORENA ARANGO GARCIA | O27: 1128625036 | P27: MADRE | Q27: Norcasia | R27: 3207510483 | S27: luizafer_815@hotmail.com | T27: 1128626485 | U27: ISABELA | V27: 0 | W27: FRANCO | X27: ARANGO | Z27: 7/23/2009 | AA27: 16 | AB27: F | AC27: 11 | AD27: francoisabela38@gmail.com | AF27: Despacho Programado | AG27: {=_xlfn.LET(_xlpm.n,COUNTIFS($B$2:$B27,$B27,$M$2:$M27,$M27),_xlpm.res,IF($M27=1,_xlfn._xlws.FILTER('TABLETAS ESTUDIANTES'!$C$2:$K$1000,'TABLETAS ESTUDIANTES'!$B$2:$B$1000=$B27),_xlfn._xlws.FILTER('PORTATIL ESTUDIANTES'!$C$2:$K$1000,'PORTATIL ESTUDIANTES'!$B$2:$B$1000=$B27)),IFERROR(INDEX(_xlpm.res,_xlpm.n,_xlfn.SEQUENCE(1,9)),""))} -> 117495005407 | AH27: INSTITUCIÓN EDUCATIVA SAN GERARDO MARIA MAYELA - SEDE PRINCIPAL | AI27: Norcasia | AJ27: ENTIDAD TERRITORIAL | AK27: COMITÉ DE FOCALIZACION 2026 | AL27: 45030 | AM27: PORTÁTIL 14" HEWLETT PACKARD, PROBOOK 445 14 INCH G11 RYZEN 3 7335U - OC 148772 | AN27: 1 | AO27: 5CD5328V4X
A28: Línea 2 — EE vinculados a Educación Superior | B28: 21879 | C28: Caldas | D28: CALDAS | E28: 17495 | F28: Norcasia | G28: 117495005407 | H28: INSTITUCION EDUCATIVA SAN GERARDO MARIA MAYELA | I28: 117495005407 | J28: INSTITUCIÓN EDUCATIVA SAN GERARDO MARIA MAYELA - SEDE PRINCIPAL | K28: URBANA | L28: 1 | M28: - | N28: ANGELA YINETH PEREZ CASALLAS | O28: 1010197892 | P28: MADRE | Q28: La variante finca la joya | R28: 3113919512 | S28: luizafer_815@hotmail.com | T28: 1028887846 | U28: ANA | V28: SOFIA | W28: HENAO | X28: PEREZ | Z28: 7/13/2009 | AA28: 16 | AB28: F | AC28: 11 | AD28: anasofiahenao1309@gmail.com | AF28: Despacho Programado | AG28: {=_xlfn.LET(_xlpm.n,COUNTIFS($B$2:$B28,$B28,$M$2:$M28,$M28),_xlpm.res,IF($M28=1,_xlfn._xlws.FILTER('TABLETAS ESTUDIANTES'!$C$2:$K$1000,'TABLETAS ESTUDIANTES'!$B$2:$B$1000=$B28),_xlfn._xlws.FILTER('PORTATIL ESTUDIANTES'!$C$2:$K$1000,'PORTATIL ESTUDIANTES'!$B$2:$B$1000=$B28)),IFERROR(INDEX(_xlpm.res,_xlpm.n,_xlfn.SEQUENCE(1,9)),""))} -> 117495005407 | AH28: INSTITUCIÓN EDUCATIVA SAN GERARDO MARIA MAYELA - SEDE PRINCIPAL | AI28: Norcasia | AJ28: ENTIDAD TERRITORIAL | AK28: COMITÉ DE FOCALIZACION 2026 | AL28: 45030 | AM28: PORTÁTIL 14" HEWLETT PACKARD, PROBOOK 445 14 INCH G11 RYZEN 3 7335U - OC 148772 | AN28: 1 | AO28: 5CD53276QB
A29: Línea 2 — EE vinculados a Educación Superior | B29: 21879 | C29: Caldas | D29: CALDAS | E29: 17495 | F29: Norcasia | G29: 117495005407 | H29: INSTITUCION EDUCATIVA SAN GERARDO MARIA MAYELA | I29: 117495005407 | J29: INSTITUCIÓN EDUCATIVA SAN GERARDO MARIA MAYELA - SEDE PRINCIPAL | K29: URBANA | L29: 1 | M29: - | N29: ADRIANA ROA HERRERA | O29: 20830406 | P29: MADRE | Q29: Carrera 5 # 10-21 | R29: 3137950163 | S29: luizafer_815@hotmail.com | T29: 1054554897 | U29: DAVID | V29: SANTIAGO | W29: HERRERA | X29: ROA | Z29: 40153 | AA29: 16 | AB29: M | AC29: 11 | AD29: cmhr20113147709606@gmail.com | AF29: Despacho Programado | AG29: {=_xlfn.LET(_xlpm.n,COUNTIFS($B$2:$B29,$B29,$M$2:$M29,$M29),_xlpm.res,IF($M29=1,_xlfn._xlws.FILTER('TABLETAS ESTUDIANTES'!$C$2:$K$1000,'TABLETAS ESTUDIANTES'!$B$2:$B$1000=$B29),_xlfn._xlws.FILTER('PORTATIL ESTUDIANTES'!$C$2:$K$1000,'PORTATIL ESTUDIANTES'!$B$2:$B$1000=$B29)),IFERROR(INDEX(_xlpm.res,_xlpm.n,_xlfn.SEQUENCE(1,9)),""))} -> 117495005407 | AH29: INSTITUCIÓN EDUCATIVA SAN GERARDO MARIA MAYELA - SEDE PRINCIPAL | AI29: Norcasia | AJ29: ENTIDAD TERRITORIAL | AK29: COMITÉ DE FOCALIZACION 2026 | AL29: 45030 | AM29: PORTÁTIL 14" HEWLETT PACKARD, PROBOOK 445 14 INCH G11 RYZEN 3 7335U - OC 148772 | AN29: 1 | AO29: 5CD5320L80
A30: Línea 2 — EE vinculados a Educación Superior | B30: 21879 | C30: Caldas | D30: CALDAS | E30: 17495 | F30: Norcasia | G30: 117495005407 | H30: INSTITUCION EDUCATIVA SAN GERARDO MARIA MAYELA | I30: 117495005407 | J30: INSTITUCIÓN EDUCATIVA SAN GERARDO MARIA MAYELA - SEDE PRINCIPAL | K30: URBANA | L30: 1 | M30: - | N30: JENNY PATRICIA OLIVARES | O30: 30351725 | P30: MADRE | Q30: Barrio: Marisol Manrique, apto: 403, bloque: 4 | R30: 3235407721 | S30: luizafer_815@hotmail.com | T30: 1128625806 | U30: SARAY | V30: LINEY | W30: GARCIA | X30: OLIVARES | Z30: 10/31/2009 | AA30: 16 | AB30: F | AC30: 11 | AD30: lineygarcia032@gmail.com | AF30: Despacho Programado | AG30: {=_xlfn.LET(_xlpm.n,COUNTIFS($B$2:$B30,$B30,$M$2:$M30,$M30),_xlpm.res,IF($M30=1,_xlfn._xlws.FILTER('TABLETAS ESTUDIANTES'!$C$2:$K$1000,'TABLETAS ESTUDIANTES'!$B$2:$B$1000=$B30),_xlfn._xlws.FILTER('PORTATIL ESTUDIANTES'!$C$2:$K$1000,'PORTATIL ESTUDIANTES'!$B$2:$B$1000=$B30)),IFERROR(INDEX(_xlpm.res,_xlpm.n,_xlfn.SEQUENCE(1,9)),""))} -> 117495005407 | AH30: INSTITUCIÓN EDUCATIVA SAN GERARDO MARIA MAYELA - SEDE PRINCIPAL | AI30: Norcasia | AJ30: ENTIDAD TERRITORIAL | AK30: COMITÉ DE FOCALIZACION 2026 | AL30: 45030 | AM30: PORTÁTIL 14" HEWLETT PACKARD, PROBOOK 445 14 INCH G11 RYZEN 3 7335U - OC 148772 | AN30: 1 | AO30: 5CD5328TY5
A31: Línea 2 — EE vinculados a Educación Superior | B31: 21879 | C31: Caldas | D31: CALDAS | E31: 17495 | F31: Norcasia | G31: 117495005407 | H31: INSTITUCION EDUCATIVA SAN GERARDO MARIA MAYELA | I31: 117495005407 | J31: INSTITUCIÓN EDUCATIVA SAN GERARDO MARIA MAYELA - SEDE PRINCIPAL | K31: URBANA | L31: 1 | M31: - | N31: ANA MILENA MORENO GARZON | O31: 52763768 | P31: MADRE | Q31: calle 14 #5-20 | R31: 3103951780 | S31: luizafer_815@hotmail.com | T31: 1128628149 | U31: HABINSON | V31: MIGUEL | W31: LOPEZ | X31: MORENO | Z31: 8/22/2009 | AA31: 16 | AB31: M | AC31: 11 | AD31: habinson22@gmail.com | AF31: Despacho Programado | AG31: {=_xlfn.LET(_xlpm.n,COUNTIFS($B$2:$B31,$B31,$M$2:$M31,$M31),_xlpm.res,IF($M31=1,_xlfn._xlws.FILTER('TABLETAS ESTUDIANTES'!$C$2:$K$1000,'TABLETAS ESTUDIANTES'!$B$2:$B$1000=$B31),_xlfn._xlws.FILTER('PORTATIL ESTUDIANTES'!$C$2:$K$1000,'PORTATIL ESTUDIANTES'!$B$2:$B$1000=$B31)),IFERROR(INDEX(_xlpm.res,_xlpm.n,_xlfn.SEQUENCE(1,9)),""))} -> 117495005407 | AH31: INSTITUCIÓN EDUCATIVA SAN GERARDO MARIA MAYELA - SEDE PRINCIPAL | AI31: Norcasia | AJ31: ENTIDAD TERRITORIAL | AK31: COMITÉ DE FOCALIZACION 2026 | AL31: 45030 | AM31: PORTÁTIL 14" HEWLETT PACKARD, PROBOOK 445 14 INCH G11 RYZEN 3 7335U - OC 148772 | AN31: 1 | AO31: 5CD532941L
A32: Línea 2 — EE vinculados a Educación Superior | B32: 21879 | C32: Caldas | D32: CALDAS | E32: 17495 | F32: Norcasia | G32: 117495005407 | H32: INSTITUCION EDUCATIVA SAN GERARDO MARIA MAYELA | I32: 117495005407 | J32: INSTITUCIÓN EDUCATIVA SAN GERARDO MARIA MAYELA - SEDE PRINCIPAL | K32: URBANA | L32: - | M32: 1 | N32: FRANCY YURLEY BETANCURT PEÑA | O32: 1128626243 | P32: MADRE | Q32: Vereda Montebello | R32: 3234821188 | S32: luizafer_815@hotmail.com | T32: 1128625920 | U32: JHOAN | V32: ALEXIS | W32: VILLAMIL | X32: BETANCURT | Z32: 2/15/2010 | AA32: 16 | AB32: M | AC32: 11 | AD32: jhoanv846@gmail.com | AF32: Despacho Programado | AG32: {=_xlfn.LET(_xlpm.n,COUNTIFS($B$2:$B32,$B32,$M$2:$M32,$M32),_xlpm.res,IF($M32=1,_xlfn._xlws.FILTER('TABLETAS ESTUDIANTES'!$C$2:$K$1000,'TABLETAS ESTUDIANTES'!$B$2:$B$1000=$B32),_xlfn._xlws.FILTER('PORTATIL ESTUDIANTES'!$C$2:$K$1000,'PORTATIL ESTUDIANTES'!$B$2:$B$1000=$B32)),IFERROR(INDEX(_xlpm.res,_xlpm.n,_xlfn.SEQUENCE(1,9)),""))} -> 117495005407 | AH32: INSTITUCIÓN EDUCATIVA SAN GERARDO MARIA MAYELA - SEDE PRINCIPAL | AI32: Norcasia | AJ32: ENTIDAD TERRITORIAL | AK32: COMITÉ DE FOCALIZACION 2026 | AL32: 45053 | AM32: BT TABLETA LENOVO IDEA TAB PRO CTO 158-25 | AN32: 1 | AO32: HA2HFAY6
A33: Línea 2 — EE vinculados a Educación Superior | B33: 21879 | C33: Caldas | D33: CALDAS | E33: 17495 | F33: Norcasia | G33: 117495005407 | H33: INSTITUCION EDUCATIVA SAN GERARDO MARIA MAYELA | I33: 117495005407 | J33: INSTITUCIÓN EDUCATIVA SAN GERARDO MARIA MAYELA - SEDE PRINCIPAL | K33: URBANA | L33: - | M33: 1 | N33: JOSE ARNULFO FLOREZ RINCON | O33: 79829558 | P33: PADRE | Q33: Poblado bajo | R33: 3057105273 | S33: luizafer_815@hotmail.com | T33: 1023386761 | U33: PAULA | V33: VALENTINA | W33: FLOREZ | X33: REYES | Z33: 11/22/2009 | AA33: 16 | AB33: F | AC33: 11 | AD33: valenfloreyes@gmail.com | AF33: Despacho Programado | AG33: {=_xlfn.LET(_xlpm.n,COUNTIFS($B$2:$B33,$B33,$M$2:$M33,$M33),_xlpm.res,IF($M33=1,_xlfn._xlws.FILTER('TABLETAS ESTUDIANTES'!$C$2:$K$1000,'TABLETAS ESTUDIANTES'!$B$2:$B$1000=$B33),_xlfn._xlws.FILTER('PORTATIL ESTUDIANTES'!$C$2:$K$1000,'PORTATIL ESTUDIANTES'!$B$2:$B$1000=$B33)),IFERROR(INDEX(_xlpm.res,_xlpm.n,_xlfn.SEQUENCE(1,9)),""))} -> 117495005407 | AH33: INSTITUCIÓN EDUCATIVA SAN GERARDO MARIA MAYELA - SEDE PRINCIPAL | AI33: Norcasia | AJ33: ENTIDAD TERRITORIAL | AK33: COMITÉ DE FOCALIZACION 2026 | AL33: 45053 | AM33: BT TABLETA LENOVO IDEA TAB PRO CTO 158-25 | AN33: 1 | AO33: HA2HGR1X
A34: Línea 2 — EE vinculados a Educación Superior | B34: 21879 | C34: Caldas | D34: CALDAS | E34: 17495 | F34: Norcasia | G34: 117495005407 | H34: INSTITUCION EDUCATIVA SAN GERARDO MARIA MAYELA | I34: 117495005407 | J34: INSTITUCIÓN EDUCATIVA SAN GERARDO MARIA MAYELA - SEDE PRINCIPAL | K34: URBANA | L34: - | M34: 1 | N34: YUDY ESNEY LONDOÑO PEÑA | O34: 1128624760 | P34: MADRE | Q34: Cra7#6-24 | R34: 3103665111 | S34: luizafer_815@hotmail.com | T34: 1054556667 | U34: ISABEL | V34: CRISTINA | W34: GOMEZ | X34: LONDOÃ‘O | Z34: 40213 | AA34: 15 | AB34: F | AC34: 11 | AD34: isabelgomezlondono2@hotmail.com | AF34: Despacho Programado | AG34: {=_xlfn.LET(_xlpm.n,COUNTIFS($B$2:$B34,$B34,$M$2:$M34,$M34),_xlpm.res,IF($M34=1,_xlfn._xlws.FILTER('TABLETAS ESTUDIANTES'!$C$2:$K$1000,'TABLETAS ESTUDIANTES'!$B$2:$B$1000=$B34),_xlfn._xlws.FILTER('PORTATIL ESTUDIANTES'!$C$2:$K$1000,'PORTATIL ESTUDIANTES'!$B$2:$B$1000=$B34)),IFERROR(INDEX(_xlpm.res,_xlpm.n,_xlfn.SEQUENCE(1,9)),""))} -> 117495005407 | AH34: INSTITUCIÓN EDUCATIVA SAN GERARDO MARIA MAYELA - SEDE PRINCIPAL | AI34: Norcasia | AJ34: ENTIDAD TERRITORIAL | AK34: COMITÉ DE FOCALIZACION 2026 | AL34: 45053 | AM34: BT TABLETA LENOVO IDEA TAB PRO CTO 158-25 | AN34: 1 | AO34: HA2HFN54
A35: Línea 2 — EE vinculados a Educación Superior | B35: 33116 | C35: Caldas | D35: CALDAS | E35: 17513 | F35: Pácora | G35: 117513000558 | H35: INSTITUCION EDUCATIVA MARCO FIDEL SUAREZ | I35: 117513000558 | J35: INSTITUCION EDUCATIVA MARCO FIDEL SUAREZ - SEDE PRINCIPAL | K35: URBANA | L35: - | M35: 1 | N35: JENNIFER MARCELA REYES RODRIGUEZ | O35: 1049620960 | P35: MADRE | Q35: Carrera 2 N. 5-35 | R35: 3204563976 | S35: luizafer_815@hotmail.com | T35: 1150435210 | U35: MARIANA | V35: SOPHIA | W35: BECERRA | X35: REYES | Z35: 39910 | AA35: 16 | AB35: F | AC35: 11 | AD35: marcrey864@gmail.com | AF35: Despacho Programado | AG35: {=_xlfn.LET(_xlpm.n,COUNTIFS($B$2:$B35,$B35,$M$2:$M35,$M35),_xlpm.res,IF($M35=1,_xlfn._xlws.FILTER('TABLETAS ESTUDIANTES'!$C$2:$K$1000,'TABLETAS ESTUDIANTES'!$B$2:$B$1000=$B35),_xlfn._xlws.FILTER('PORTATIL ESTUDIANTES'!$C$2:$K$1000,'PORTATIL ESTUDIANTES'!$B$2:$B$1000=$B35)),IFERROR(INDEX(_xlpm.res,_xlpm.n,_xlfn.SEQUENCE(1,9)),""))} -> 117513000558 | AH35: INSTITUCION EDUCATIVA MARCO FIDEL SUAREZ - SEDE PRINCIPAL | AI35: Pácora | AJ35: ENTIDAD TERRITORIAL | AK35: COMITÉ DE FOCALIZACION 2026 | AL35: 45053 | AM35: BT TABLETA LENOVO IDEA TAB PRO CTO 158-25 | AN35: 1 | AO35: HA2HE653
A36: Línea 2 — EE vinculados a Educación Superior | B36: 84717 | C36: Caldas | D36: CALDAS | E36: 17541 | F36: Pensilvania | G36: 217541001360 | H36: INSTITUCION EDUCATIVA CAMILO OLIMPO CARDONA | I36: 217541001360 | J36: INSTITUCION EDUCATIVA CAMILO OLIMPO CARDONA - SEDE PRINCIPAL | K36: RURAL | L36: - | M36: 1 | N36: ROSALBA QUICENO JARAMILLO | O36: 33745247 | P36: MADRE | Q36: El Higueron | R36: 3116476363 | S36: luizafer_815@hotmail.com | T36: 1054870602 | U36: DIANA | V36: SOFIA | W36: MURILLO | X36: QUICENO | Z36: 40091 | AA36: 16 | AB36: F | AC36: 11 | AD36: murillosofi2009@gmail.com | AF36: Despacho Programado | AG36: {=_xlfn.LET(_xlpm.n,COUNTIFS($B$2:$B36,$B36,$M$2:$M36,$M36),_xlpm.res,IF($M36=1,_xlfn._xlws.FILTER('TABLETAS ESTUDIANTES'!$C$2:$K$1000,'TABLETAS ESTUDIANTES'!$B$2:$B$1000=$B36),_xlfn._xlws.FILTER('PORTATIL ESTUDIANTES'!$C$2:$K$1000,'PORTATIL ESTUDIANTES'!$B$2:$B$1000=$B36)),IFERROR(INDEX(_xlpm.res,_xlpm.n,_xlfn.SEQUENCE(1,9)),""))} -> 217541001360 | AH36: INSTITUCION EDUCATIVA CAMILO OLIMPO CARDONA - SEDE PRINCIPAL | AI36: Pensilvania | AJ36: ENTIDAD TERRITORIAL | AK36: COMITÉ DE FOCALIZACION 2026 | AL36: 45053 | AM36: BT TABLETA LENOVO IDEA TAB PRO CTO 158-25 | AN36: 1 | AO36: HA2HGSGZ
A37: Línea 2 — EE vinculados a Educación Superior | B37: 84717 | C37: Caldas | D37: CALDAS | E37: 17541 | F37: Pensilvania | G37: 217541001360 | H37: INSTITUCION EDUCATIVA CAMILO OLIMPO CARDONA | I37: 217541001360 | J37: INSTITUCION EDUCATIVA CAMILO OLIMPO CARDONA - SEDE PRINCIPAL | K37: RURAL | L37: - | M37: 1 | N37: LADY JOHANA JIMÉNEZ GONZÁLEZ | O37: 1057782107 | P37: MADRE | Q37: La soledad | R37: 3128970837 | S37: luizafer_815@hotmail.com | T37: 1054870861 | U37: KAROL | V37: XIMENA | W37: QUINTERO | X37: JIMENEZ | Z37: 40062 | AA37: 16 | AB37: F | AC37: 11 | AD37: karolquinterojimenez5@gmail.com | AF37: Despacho Programado | AG37: {=_xlfn.LET(_xlpm.n,COUNTIFS($B$2:$B37,$B37,$M$2:$M37,$M37),_xlpm.res,IF($M37=1,_xlfn._xlws.FILTER('TABLETAS ESTUDIANTES'!$C$2:$K$1000,'TABLETAS ESTUDIANTES'!$B$2:$B$1000=$B37),_xlfn._xlws.FILTER('PORTATIL ESTUDIANTES'!$C$2:$K$1000,'PORTATIL ESTUDIANTES'!$B$2:$B$1000=$B37)),IFERROR(INDEX(_xlpm.res,_xlpm.n,_xlfn.SEQUENCE(1,9)),""))} -> 217541001360 | AH37: INSTITUCION EDUCATIVA CAMILO OLIMPO CARDONA - SEDE PRINCIPAL | AI37: Pensilvania | AJ37: ENTIDAD TERRITORIAL | AK37: COMITÉ DE FOCALIZACION 2026 | AL37: 45053 | AM37: BT TABLETA LENOVO IDEA TAB PRO CTO 158-25 | AN37: 1 | AO37: HA2HEC5J
A38: Línea 2 — EE vinculados a Educación Superior | B38: 84717 | C38: Caldas | D38: CALDAS | E38: 17541 | F38: Pensilvania | G38: 217541001360 | H38: INSTITUCION EDUCATIVA CAMILO OLIMPO CARDONA | I38: 217541001360 | J38: INSTITUCION EDUCATIVA CAMILO OLIMPO CARDONA - SEDE PRINCIPAL | K38: RURAL | L38: - | M38: 1 | N38: LUZ LILIANA ALARCON LÓPEZ | O38: 1010084314 | P38: MADRE | Q38: vereda Barreto | R38: 3223952614 | S38: luizafer_815@hotmail.com | T38: 1161213361 | U38: YENNI | V38: MARELVI | W38: REYES | X38: ALARCON | Z38: 2/26/2009 | AA38: 17 | AB38: F | AC38: 11 | AD38: yennireyes084@gmail.com | AF38: Despacho Programado | AG38: {=_xlfn.LET(_xlpm.n,COUNTIFS($B$2:$B38,$B38,$M$2:$M38,$M38),_xlpm.res,IF($M38=1,_xlfn._xlws.FILTER('TABLETAS ESTUDIANTES'!$C$2:$K$1000,'TABLETAS ESTUDIANTES'!$B$2:$B$1000=$B38),_xlfn._xlws.FILTER('PORTATIL ESTUDIANTES'!$C$2:$K$1000,'PORTATIL ESTUDIANTES'!$B$2:$B$1000=$B38)),IFERROR(INDEX(_xlpm.res,_xlpm.n,_xlfn.SEQUENCE(1,9)),""))} -> 217541001360 | AH38: INSTITUCION EDUCATIVA CAMILO OLIMPO CARDONA - SEDE PRINCIPAL | AI38: Pensilvania | AJ38: ENTIDAD TERRITORIAL | AK38: COMITÉ DE FOCALIZACION 2026 | AL38: 45053 | AM38: BT TABLETA LENOVO IDEA TAB PRO CTO 158-25 | AN38: 1 | AO38: HA2HEQ3G
A39: Línea 2 — EE vinculados a Educación Superior | B39: 84717 | C39: Caldas | D39: CALDAS | E39: 17541 | F39: Pensilvania | G39: 217541001360 | H39: INSTITUCION EDUCATIVA CAMILO OLIMPO CARDONA | I39: 217541001360 | J39: INSTITUCION EDUCATIVA CAMILO OLIMPO CARDONA - SEDE PRINCIPAL | K39: RURAL | L39: - | M39: 1 | N39: BLANCA LEDIS GALLEGO GUTIERREZ | O39: 24738327 | P39: MADRE | Q39: el higuerón | R39: 3123923709 | S39: luizafer_815@hotmail.com | T39: 1059119432 | U39: GERONIMO | V39: 0 | W39: JIMENEZ | X39: GALLEGO | Z39: 2/15/2009 | AA39: 17 | AB39: M | AC39: 11 | AD39: aaosoriov1@gmail.com | AF39: Despacho Programado | AG39: {=_xlfn.LET(_xlpm.n,COUNTIFS($B$2:$B39,$B39,$M$2:$M39,$M39),_xlpm.res,IF($M39=1,_xlfn._xlws.FILTER('TABLETAS ESTUDIANTES'!$C$2:$K$1000,'TABLETAS ESTUDIANTES'!$B$2:$B$1000=$B39),_xlfn._xlws.FILTER('PORTATIL ESTUDIANTES'!$C$2:$K$1000,'PORTATIL ESTUDIANTES'!$B$2:$B$1000=$B39)),IFERROR(INDEX(_xlpm.res,_xlpm.n,_xlfn.SEQUENCE(1,9)),""))} -> 217541001360 | AH39: INSTITUCION EDUCATIVA CAMILO OLIMPO CARDONA - SEDE PRINCIPAL | AI39: Pensilvania | AJ39: ENTIDAD TERRITORIAL | AK39: COMITÉ DE FOCALIZACION 2026 | AL39: 45053 | AM39: BT TABLETA LENOVO IDEA TAB PRO CTO 158-25 | AN39: 1 | AO39: HA2HFC12
A40: Línea 2 — EE vinculados a Educación Superior | B40: 84717 | C40: Caldas | D40: CALDAS | E40: 17541 | F40: Pensilvania | G40: 217541001360 | H40: INSTITUCION EDUCATIVA CAMILO OLIMPO CARDONA | I40: 217541001360 | J40: INSTITUCION EDUCATIVA CAMILO OLIMPO CARDONA - SEDE PRINCIPAL | K40: RURAL | L40: - | M40: 1 | N40: SANTOS REYES CARRILLO | O40: 9496622 | P40: PADRE | Q40: Vereda barreto | R40: 3169947563 | S40: luizafer_815@hotmail.com | T40: 1055552513 | U40: GRICELDA | V40: JASSBLEIDY | W40: REYES | X40: TORRES | Z40: 4/16/2010 | AA40: 15 | AB40: F | AC40: 11 | AD40: aaosoriov1@gmail.com | AF40: Despacho Programado | AG40: {=_xlfn.LET(_xlpm.n,COUNTIFS($B$2:$B40,$B40,$M$2:$M40,$M40),_xlpm.res,IF($M40=1,_xlfn._xlws.FILTER('TABLETAS ESTUDIANTES'!$C$2:$K$1000,'TABLETAS ESTUDIANTES'!$B$2:$B$1000=$B40),_xlfn._xlws.FILTER('PORTATIL ESTUDIANTES'!$C$2:$K$1000,'PORTATIL ESTUDIANTES'!$B$2:$B$1000=$B40)),IFERROR(INDEX(_xlpm.res,_xlpm.n,_xlfn.SEQUENCE(1,9)),""))} -> 217541001360 | AH40: INSTITUCION EDUCATIVA CAMILO OLIMPO CARDONA - SEDE PRINCIPAL | AI40: Pensilvania | AJ40: ENTIDAD TERRITORIAL | AK40: COMITÉ DE FOCALIZACION 2026 | AL40: 45053 | AM40: BT TABLETA LENOVO IDEA TAB PRO CTO 158-25 | AN40: 1 | AO40: HA2HFB0X
...

Sheet PORTATIL ESTUDIANTES
A1: Item | B1: Radicado | C1: Dane sede | D1: Lugar de Entrega | E1: Ubicacion institucional Educativa(P-D-M) | F1: N° Orden de Transporte | G1: Programa | H1: Referencia | I1: Descripcion | J1: Cantidad | K1: Serial
A2: 1 | B2: 21878 | C2: 117042000650 | D2: INSTITUCION EDUCATIVA ESCUELA NORMAL SUPERIOR REBECA SIERRA CARDONA - SEDE PRINCIPAL | E2: Anserma | F2: ENTIDAD TERRITORIAL | G2: COMITÉ DE FOCALIZACION 2026 | H2: 45030 | I2: PORTÁTIL 14" HEWLETT PACKARD, PROBOOK 445 14 INCH G11 RYZEN 3 7335U - OC 148772 | J2: 1 | K2: 5CD53293KF
A3: 2 | B3: 1181 | C3: 117050000316 | D3: INSTITUCION EDUCATIVA ESCUELA NORMAL SUPERIOR SAGRADO CORAZON - SEDE PRINCIPAL | E3: Aranzazu | F3: ENTIDAD TERRITORIAL | G3: COMITÉ DE FOCALIZACION 2026 | H3: 45030 | I3: PORTÁTIL 14" HEWLETT PACKARD, PROBOOK 445 14 INCH G11 RYZEN 3 7335U - OC 148772 | J3: 1 | K3: 5CD53276HP
A4: 3 | B4: 2994 | C4: 117380000185 | D4: INSTITUCION EDUCATIVA MARCO FIDEL SUAREZ - SEDE PRINCIPAL | E4: La Dorada | F4: ENTIDAD TERRITORIAL | G4: COMITÉ DE FOCALIZACION 2026 | H4: 45030 | I4: PORTÁTIL 14" HEWLETT PACKARD, PROBOOK 445 14 INCH G11 RYZEN 3 7335U - OC 148772 | J4: 1 | K4: 5CD53276QZ
A5: 4 | B5: 2994 | C5: 117380000185 | D5: INSTITUCION EDUCATIVA MARCO FIDEL SUAREZ - SEDE PRINCIPAL | E5: La Dorada | F5: ENTIDAD TERRITORIAL | G5: COMITÉ DE FOCALIZACION 2026 | H5: 45030 | I5: PORTÁTIL 14" HEWLETT PACKARD, PROBOOK 445 14 INCH G11 RYZEN 3 7335U - OC 148772 | J5: 1 | K5: 5CD5320L6M
A6: 5 | B6: 2994 | C6: 117380000185 | D6: INSTITUCION EDUCATIVA MARCO FIDEL SUAREZ - SEDE PRINCIPAL | E6: La Dorada | F6: ENTIDAD TERRITORIAL | G6: COMITÉ DE FOCALIZACION 2026 | H6: 45030 | I6: PORTÁTIL 14" HEWLETT PACKARD, PROBOOK 445 14 INCH G11 RYZEN 3 7335U - OC 148772 | J6: 1 | K6: C50VVLA#ABM
A7: 6 | B7: 9089 | C7: 217444000138 | D7: INSTITUCION EDUCATIVA EL PLACER - SEDE PRINCIPAL | E7: Marquetalia | F7: ENTIDAD TERRITORIAL | G7: COMITÉ DE FOCALIZACION 2026 | H7: 45030 | I7: PORTÁTIL 14" HEWLETT PACKARD, PROBOOK 445 14 INCH G11 RYZEN 3 7335U - OC 148772 | J7: 1 | K7: 5CD532768Y
A8: 7 | B8: 9089 | C8: 217444000138 | D8: INSTITUCION EDUCATIVA EL PLACER - SEDE PRINCIPAL | E8: Marquetalia | F8: ENTIDAD TERRITORIAL | G8: COMITÉ DE FOCALIZACION 2026 | H8: 45030 | I8: PORTÁTIL 14" HEWLETT PACKARD, PROBOOK 445 14 INCH G11 RYZEN 3 7335U - OC 148772 | J8: 1 | K8: 5CD53276Z1
A9: 8 | B9: 21879 | C9: 117495005407 | D9: INSTITUCIÓN EDUCATIVA SAN GERARDO MARIA MAYELA - SEDE PRINCIPAL | E9: Norcasia | F9: ENTIDAD TERRITORIAL | G9: COMITÉ DE FOCALIZACION 2026 | H9: 45030 | I9: PORTÁTIL 14" HEWLETT PACKARD, PROBOOK 445 14 INCH G11 RYZEN 3 7335U - OC 148772 | J9: 1 | K9: 5CD532766F
A10: 9 | B10: 21879 | C10: 117495005407 | D10: INSTITUCIÓN EDUCATIVA SAN GERARDO MARIA MAYELA - SEDE PRINCIPAL | E10: Norcasia | F10: ENTIDAD TERRITORIAL | G10: COMITÉ DE FOCALIZACION 2026 | H10: 45030 | I10: PORTÁTIL 14" HEWLETT PACKARD, PROBOOK 445 14 INCH G11 RYZEN 3 7335U - OC 148772 | J10: 1 | K10: 5CD5320LGS
A11: 10 | B11: 21879 | C11: 117495005407 | D11: INSTITUCIÓN EDUCATIVA SAN GERARDO MARIA MAYELA - SEDE PRINCIPAL | E11: Norcasia | F11: ENTIDAD TERRITORIAL | G11: COMITÉ DE FOCALIZACION 2026 | H11: 45030 | I11: PORTÁTIL 14" HEWLETT PACKARD, PROBOOK 445 14 INCH G11 RYZEN 3 7335U - OC 148772 | J11: 1 | K11: 5CD5328V62
A12: 11 | B12: 21879 | C12: 117495005407 | D12: INSTITUCIÓN EDUCATIVA SAN GERARDO MARIA MAYELA - SEDE PRINCIPAL | E12: Norcasia | F12: ENTIDAD TERRITORIAL | G12: COMITÉ DE FOCALIZACION 2026 | H12: 45030 | I12: PORTÁTIL 14" HEWLETT PACKARD, PROBOOK 445 14 INCH G11 RYZEN 3 7335U - OC 148772 | J12: 1 | K12: 5CD5320LFT
A13: 12 | B13: 21879 | C13: 117495005407 | D13: INSTITUCIÓN EDUCATIVA SAN GERARDO MARIA MAYELA - SEDE PRINCIPAL | E13: Norcasia | F13: ENTIDAD TERRITORIAL | G13: COMITÉ DE FOCALIZACION 2026 | H13: 45030 | I13: PORTÁTIL 14" HEWLETT PACKARD, PROBOOK 445 14 INCH G11 RYZEN 3 7335U - OC 148772 | J13: 1 | K13: 5CD5328V4X
... A31: 30 | B31: 33370 | C31: 217662000964 | D31: INSTITUCION EDUCATIVA FELIX NARANJO - SEDE PRINCIPAL | E31: Samaná | F31: ENTIDAD TERRITORIAL | G31: COMITÉ DE FOCALIZACION 2026 | H31: 45030 | I31: PORTÁTIL 14" HEWLETT PACKARD, PROBOOK 445 14 INCH G11 RYZEN 3 7335U - OC 148772 | J31: 1 | K31: 5CD53293V3

Sheet TABLETAS ESTUDIANTES
A1: Item | B1: Radicado | C1: Dane sede | D1: Lugar de Entrega | E1: Ubicacion institucional Educativa(P-D-M) | F1: N° Orden de Transporte | G1: Programa | H1: Referencia | I1: Descripcion | J1: Cantidad | K1: Serial
A2: 1 | B2: 86471 | C2: 117013000306 | D2: INSTITUCION EDUCATIVA MARINO GOMEZ ESTRADA - SEDE PRINCIPAL | E2: Aguadas | F2: ENTIDAD TERRITORIAL | G2: COMITÉ DE FOCALIZACION 2026 | H2: 45053 | I2: BT TABLETA LENOVO IDEA TAB PRO CTO 158-25 | J2: 1 | K2: HA2HES5G
A3: 2 | B3: 86471 | C3: 117013000306 | D3: INSTITUCION EDUCATIVA MARINO GOMEZ ESTRADA - SEDE PRINCIPAL | E3: Aguadas | F3: ENTIDAD TERRITORIAL | G3: COMITÉ DE FOCALIZACION 2026 | H3: 45053 | I3: BT TABLETA LENOVO IDEA TAB PRO CTO 158-25 | J3: 1 | K3: HA2HDZEV
A4: 3 | B4: 32741 | C4: 117088000255 | D4: INSTITUCION EDUCATIVA CRISTO REY - SEDE PRINCIPAL | E4: Belalcázar | F4: ENTIDAD TERRITORIAL | G4: COMITÉ DE FOCALIZACION 2026 | H4: 45053 | I4: BT TABLETA LENOVO IDEA TAB PRO CTO 158-25 | J4: 1 | K4: HA2HF5YE
A5: 4 | B5: 32741 | C5: 117088000255 | D5: INSTITUCION EDUCATIVA CRISTO REY - SEDE PRINCIPAL | E5: Belalcázar | F5: ENTIDAD TERRITORIAL | G5: COMITÉ DE FOCALIZACION 2026 | H5: 45053 | I5: BT TABLETA LENOVO IDEA TAB PRO CTO 158-25 | J5: 1 | K5: HA2HFL9K
A6: 5 | B6: 32741 | C6: 117088000255 | D6: INSTITUCION EDUCATIVA CRISTO REY - SEDE PRINCIPAL | E6: Belalcázar | F6: ENTIDAD TERRITORIAL | G6: COMITÉ DE FOCALIZACION 2026 | H6: 45053 | I6: BT TABLETA LENOVO IDEA TAB PRO CTO 158-25 | J6: 1 | K6: HA2HF3WN
A7: 6 | B7: 32741 | C7: 117088000255 | D7: INSTITUCION EDUCATIVA CRISTO REY - SEDE PRINCIPAL | E7: Belalcázar | F7: ENTIDAD TERRITORIAL | G7: COMITÉ DE FOCALIZACION 2026 | H7: 45053 | I7: BT TABLETA LENOVO IDEA TAB PRO CTO 158-25 | J7: 1 | K7: HA2HEQ33
A8: 7 | B8: 32751 | C8: 117174000292 | D8: INSTITUCIÓN EDUCATIVA SAN FRANCISCO DE PAULA - SEDE PRINCIPAL | E8: Chinchiná | F8: ENTIDAD TERRITORIAL | G8: COMITÉ DE FOCALIZACION 2026 | H8: 45053 | I8: BT TABLETA LENOVO IDEA TAB PRO CTO 158-25 | J8: 1 | K8: HA2HFZ91
A9: 8 | B9: 18499 | C9: 117174000349 | D9: INSTITUCIÓN EDUCATIVA SANTA TERESITA - SEDE PRINCIPAL | E9: Chinchiná | F9: ENTIDAD TERRITORIAL | G9: COMITÉ DE FOCALIZACION 2026 | H9: 45053 | I9: BT TABLETA LENOVO IDEA TAB PRO CTO 158-25 | J9: 1 | K9: HA2HG0GP
A10: 9 | B10: 18499 | C10: 117174000349 | D10: INSTITUCIÓN EDUCATIVA SANTA TERESITA - SEDE PRINCIPAL | E10: Chinchiná | F10: ENTIDAD TERRITORIAL | G10: COMITÉ DE FOCALIZACION 2026 | H10: 45053 | I10: BT TABLETA LENOVO IDEA TAB PRO CTO 158-25 | J10: 1 | K10: HA2HES59
A11: 10 | B11: 18499 | C11: 117174000349 | D11: INSTITUCIÓN EDUCATIVA SANTA TERESITA - SEDE PRINCIPAL | E11: Chinchiná | F11: ENTIDAD TERRITORIAL | G11: COMITÉ DE FOCALIZACION 2026 | H11: 45053 | I11: BT TABLETA LENOVO IDEA TAB PRO CTO 158-25 | J11: 1 | K11: HA2HDZLA
A12: 11 | B12: 18499 | C12: 117174000349 | D12: INSTITUCIÓN EDUCATIVA SANTA TERESITA - SEDE PRINCIPAL | E12: Chinchiná | F12: ENTIDAD TERRITORIAL | G12: COMITÉ DE FOCALIZACION 2026 | H12: 45053 | I12: BT TABLETA LENOVO IDEA TAB PRO CTO 158-25 | J12: 1 | K12: HA2HGSRY
A13: 12 | B13: 18499 | C13: 117174000349 | D13: INSTITUCIÓN EDUCATIVA SANTA TERESITA - SEDE PRINCIPAL | E13: Chinchiná | F13: ENTIDAD TERRITORIAL | G13: COMITÉ DE FOCALIZACION 2026 | H13: 45053 | I13: BT TABLETA LENOVO IDEA TAB PRO CTO 158-25 | J13: 1 | K13: HA2HDHTY
... A35: 34 | B35: 84728 | C35: 117614000711 | D35: INSTITUCION EDUCATIVA LOS FUNDADORES - SEDE PRINCIPAL | E35: Riosucio | F35: ENTIDAD TERRITORIAL | G35: COMITÉ DE FOCALIZACION 2026 | H35: 45053 | I35: BT TABLETA LENOVO IDEA TAB PRO CTO 158-25 | J35: 1 | K35: HA2HFAZX
A36: 35 | B36: 16909 | C36: 117616000696 | D36: INSTITUCION EDUCATIVA MARIA INMACULADA - SEDE PRINCIPAL | E36: Risaralda | F36: ENTIDAD TERRITORIAL | G36: COMITÉ DE FOCALIZACION 2026 | H36: HA2HGSSK | I36: BT TABLETA LENOVO IDEA TAB PRO CTO 158-25 | J36: 1 | K36: HA2HES87
A37: 36 | B37: 16909 | C37: 117616000696 | D37: INSTITUCION EDUCATIVA MARIA INMACULADA - SEDE PRINCIPAL | E37: Risaralda | F37: ENTIDAD TERRITORIAL | G37: COMITÉ DE FOCALIZACION 2026 | H37: 45053 | I37: BT TABLETA LENOVO IDEA TAB PRO CTO 158-25 | J37: 1 | K37: HA2HGSSK
A38: 37 | B38: 10229 | C38: 117653000647 | D38: INSTITUCION EDUCATIVA DE LA PRESENTACION - SEDE PRINCIPAL | E38: Salamina | F38: ENTIDAD TERRITORIAL | G38: COMITÉ DE FOCALIZACION 2026 | H38: 45053 | I38: BT TABLETA LENOVO IDEA TAB PRO CTO 158-25 | J38: 1 | K38: HA2HGSH6
A39: 38 | B39: 10229 | C39: 117653000647 | D39: INSTITUCION EDUCATIVA DE LA PRESENTACION - SEDE PRINCIPAL | E39: Salamina | F39: ENTIDAD TERRITORIAL | G39: COMITÉ DE FOCALIZACION 2026 | H39: 45053 | I39: BT TABLETA LENOVO IDEA TAB PRO CTO 158-25 | J39: 1 | K39: HA2HFZCX
A40: 39 | B40: 10229 | C40: 117653000647 | D40: INSTITUCION EDUCATIVA DE LA PRESENTACION - SEDE PRINCIPAL | E40: Salamina | F40: ENTIDAD TERRITORIAL | G40: COMITÉ DE FOCALIZACION 2026 | H40: 45053 | I40: BT TABLETA LENOVO IDEA TAB PRO CTO 158-25 | J40: 1 | K40: HA2HEL54
A41: 40 | B41: 10229 | C41: 117653000647 | D41: INSTITUCION EDUCATIVA DE LA PRESENTACION - SEDE PRINCIPAL | E41: Salamina | F41: ENTIDAD TERRITORIAL | G41: COMITÉ DE FOCALIZACION 2026 | H41: 45053 | I41: BT TABLETA LENOVO IDEA TAB PRO CTO 158-25 | J41: 1 | K41: HA2HFD2A
A42: 41 | B42: 10229 | C42: 117653000647 | D42: INSTITUCION EDUCATIVA DE LA PRESENTACION - SEDE PRINCIPAL | E42: Salamina | F42: ENTIDAD TERRITORIAL | G42: COMITÉ DE FOCALIZACION 2026 | H42: 45053 | I42: BT TABLETA LENOVO IDEA TAB PRO CTO 158-25 | J42: 1 | K42: HA2HCYLP
A43: 42 | B43: 10229 | C43: 117653000647 | D43: INSTITUCION EDUCATIVA DE LA PRESENTACION - SEDE PRINCIPAL | E43: Salamina | F43: ENTIDAD TERRITORIAL | G43: COMITÉ DE FOCALIZACION 2026 | H43: 45053 | I43: BT TABLETA LENOVO IDEA TAB PRO CTO 158-25 | J43: 1 | K43: HA2HFJFN
A44: 43 | B44: 10229 | C44: 117653000647 | D44: INSTITUCION EDUCATIVA DE LA PRESENTACION - SEDE PRINCIPAL | E44: Salamina | F44: ENTIDAD TERRITORIAL | G44: COMITÉ DE FOCALIZACION 2026 | H44: 45053 | I44: BT TABLETA LENOVO IDEA TAB PRO CTO 158-25 | J44: 1 | K44: HA2HGRGK
A45: 44 | B45: 10229 | C45: 117653000647 | D45: INSTITUCION EDUCATIVA DE LA PRESENTACION - SEDE PRINCIPAL | E45: Salamina | F45: ENTIDAD TERRITORIAL | G45: COMITÉ DE FOCALIZACION 2026 | H45: 45053 | I45: BT TABLETA LENOVO IDEA TAB PRO CTO 158-25 | J45: 1 | K45: HA2HEN15
A46: 45 | B46: 10229 | C46: 117653000647 | D46: INSTITUCION EDUCATIVA DE LA PRESENTACION - SEDE PRINCIPAL | E46: Salamina | F46: ENTIDAD TERRITORIAL | G46: COMITÉ DE FOCALIZACION 2026 | H46: 45053 | I46: BT TABLETA LENOVO IDEA TAB PRO CTO 158-25 | J46: 1 | K46: HA2HG1J2
